Workbook

Sheet Run55
L1: 25569
A4: series | B4: facility | C4: run number | D4: events per file | E4: randoms | F4: duration | G4: data type | H4: bias | I4: diagnosis | J4: seriesid string | K4: date/time | L4: unixtime (min) | M4: my diag | N4: notes | O4: level | P4: levdiag
A5: 07151208_1609 | B5: UMN | C5: 55 | D5: 2000 | E5: 1000 | F5: 30 | G5: bg | H5: side 1: -4, side 2: 4 | I5: good | J5: =""""&A5&"""" -> "07151208_1609" | K5: =DATE(2000+MID(A5,3,2),MID(A5,5,2),MID(A5,7,2))+TIME(MID(A5,10,2),MID(A5,12,2),0) -> 42346.673 | L5: =(K5-25569)*24*60 -> 24159849 | M5: labview
A6: 07151208_1623 | B6: UMN | C6: 55 | D6: 2000 | E6: 1000 | F6: 30 | G6: bg | H6: side 1: -4, side 2: 4 | I6: good | J6: =""""&A6&"""" -> "07151208_1623" | K6: =DATE(2000+MID(A6,3,2),MID(A6,5,2),MID(A6,7,2))+TIME(MID(A6,10,2),MID(A6,12,2),0) -> 42346.683 | L6: =(K6-25569)*24*60 -> 24159863 | M6: labview
A7: 07151208_1644 | B7: UMN | C7: 55 | D7: 2000 | E7: 1000 | F7: 30 | G7: bg | H7: side 1: -4, side 2: 4 | I7: good | J7: =""""&A7&"""" -> "07151208_1644" | K7: =DATE(2000+MID(A7,3,2),MID(A7,5,2),MID(A7,7,2))+TIME(MID(A7,10,2),MID(A7,12,2),0) -> 42346.697 | L7: =(K7-25569)*24*60 -> 24159884 | M7: labview
A8: 07151208_1744 | B8: UMN | C8: 55 | D8: 2000 | E8: 1000 | F8: 30 | G8: bg | H8: side 1: 4, side 2: -4 | I8: good | J8: =""""&A8&"""" -> "07151208_1744" | K8: =DATE(2000+MID(A8,3,2),MID(A8,5,2),MID(A8,7,2))+TIME(MID(A8,10,2),MID(A8,12,2),0) -> 42346.739 | L8: =(K8-25569)*24*60 -> 24159944 | M8: labview
A9: 07151208_1843 | B9: UMN | C9: 55 | D9: 2000 | E9: 1000 | F9: 30 | G9: bg | H9: side 1: -4, side 2: 4 | I9: good | J9: =""""&A9&"""" -> "07151208_1843" | K9: =DATE(2000+MID(A9,3,2),MID(A9,5,2),MID(A9,7,2))+TIME(MID(A9,10,2),MID(A9,12,2),0) -> 42346.78 | L9: =(K9-25569)*24*60 -> 24160003 | M9: labview
A10: 07151208_1949 | B10: UMN | C10: 55 | D10: 2000 | E10: 1000 | F10: 30 | G10: bg | H10: side 1: 4, side 2: -4 | I10: good | J10: =""""&A10&"""" -> "07151208_1949" | K10: =DATE(2000+MID(A10,3,2),MID(A10,5,2),MID(A10,7,2))+TIME(MID(A10,10,2),MID(A10,12,2),0) -> 42346.826 | L10: =(K10-25569)*24*60 -> 24160069 | M10: labview
A11: 07151208_2049 | B11: UMN | C11: 55 | D11: 2000 | E11: 1000 | F11: 30 | G11: bg | H11: side 1: -4, side 2: 4 | I11: good | J11: =""""&A11&"""" -> "07151208_2049" | K11: =DATE(2000+MID(A11,3,2),MID(A11,5,2),MID(A11,7,2))+TIME(MID(A11,10,2),MID(A11,12,2),0) -> 42346.867 | L11: =(K11-25569)*24*60 -> 24160129 | M11: labview
A12: 07151208_2148 | B12: UMN | C12: 55 | D12: 2000 | E12: 1000 | F12: 30 | G12: bg | H12: side 1: 4, side 2: -4 | I12: good | J12: =""""&A12&"""" -> "07151208_2148" | K12: =DATE(2000+MID(A12,3,2),MID(A12,5,2),MID(A12,7,2))+TIME(MID(A12,10,2),MID(A12,12,2),0) -> 42346.908 | L12: =(K12-25569)*24*60 -> 24160188 | M12: labview
A13: 07151208_2248 | B13: UMN | C13: 55 | D13: 2000 | E13: 1000 | F13: 30 | G13: bg | H13: side 1: -4, side 2: 4 | I13: good | J13: =""""&A13&"""" -> "07151208_2248" | K13: =DATE(2000+MID(A13,3,2),MID(A13,5,2),MID(A13,7,2))+TIME(MID(A13,10,2),MID(A13,12,2),0) -> 42346.95 | L13: =(K13-25569)*24*60 -> 24160248 | M13: labview
A14: 07151208_2348 | B14: UMN | C14: 55 | D14: 2000 | E14: 1000 | F14: 30 | G14: bg | H14: side 1: 4, side 2: -4 | I14: good | J14: =""""&A14&"""" -> "07151208_2348" | K14: =DATE(2000+MID(A14,3,2),MID(A14,5,2),MID(A14,7,2))+TIME(MID(A14,10,2),MID(A14,12,2),0) -> 42346.992 | L14: =(K14-25569)*24*60 -> 24160308 | M14: labview
A15: 07151209_0048 | B15: UMN | C15: 55 | D15: 2000 | E15: 1000 | F15: 30 | G15: bg | H15: side 1: -4, side 2: 4 | I15: good | J15: =""""&A15&"""" -> "07151209_0048" | K15: =DATE(2000+MID(A15,3,2),MID(A15,5,2),MID(A15,7,2))+TIME(MID(A15,10,2),MID(A15,12,2),0) -> 42347.033 | L15: =(K15-25569)*24*60 -> 24160368 | M15: labview
A16: 07151209_0147 | B16: UMN | C16: 55 | D16: 2000 | E16: 1000 | F16: 30 | G16: bg | H16: side 1: 4, side 2: -4 | I16: good | J16: =""""&A16&"""" -> "07151209_0147" | K16: =DATE(2000+MID(A16,3,2),MID(A16,5,2),MID(A16,7,2))+TIME(MID(A16,10,2),MID(A16,12,2),0) -> 42347.074 | L16: =(K16-25569)*24*60 -> 24160427 | M16: labview
... A22: 07151209_0750 | B22: UMN | C22: 55 | D22: 2000 | E22: 1000 | F22: 30 | G22: bg | H22: side 1: 4, side 2: -4 | I22: good | J22: =""""&A22&"""" -> "07151209_0750" | K22: =DATE(2000+MID(A22,3,2),MID(A22,5,2),MID(A22,7,2))+TIME(MID(A22,10,2),MID(A22,12,2),0) -> 42347.326 | L22: =(K22-25569)*24*60 -> 24160790 | M22: labview
A23: 07151216_1700 | B23: UMN | C23: 55 | D23: null | E23: 0 | F23: 1 | G23: bg | H23: side 1: 0, side 2: 0 | I23: good | J23: =""""&A23&"""" -> "07151216_1700" | K23: =DATE(2000+MID(A23,3,2),MID(A23,5,2),MID(A23,7,2))+TIME(MID(A23,10,2),MID(A23,12,2),0) -> 42354.708 | L23: =(K23-25569)*24*60 -> 24171420 | M23: np | N23: pulse viewer accident? | O23: =(VLOOKUP(K23,Sheet3!A:E,4)-VLOOKUP(K23,Sheet3!A:E,3))/(VLOOKUP(K23,Sheet3!A:E,2)-VLOOKUP(K23,Sheet3!A:E,1))*(K23-VLOOKUP(K23,Sheet3!A:E,1))+VLOOKUP(K23,Sheet3!A:E,3) -> 0.76722255 | P23: =IF(AND(O23>0.2,O23<0.7),"ok","bad") -> bad
A24: 07151211_1835 | B24: UMN | C24: 55 | D24: null | E24: 1000 | F24: 31 | G24: bg | H24: side 1: -3.999, side 2: 4.4872 | I24: good | J24: =""""&A24&"""" -> "07151211_1835" | K24: =DATE(2000+MID(A24,3,2),MID(A24,5,2),MID(A24,7,2))+TIME(MID(A24,10,2),MID(A24,12,2),0) -> 42349.774 | L24: =(K24-25569)*24*60 -> 24164315 | M24: np | N24: not sure | O24: =(VLOOKUP(K24,Sheet3!A:E,4)-VLOOKUP(K24,Sheet3!A:E,3))/(VLOOKUP(K24,Sheet3!A:E,2)-VLOOKUP(K24,Sheet3!A:E,1))*(K24-VLOOKUP(K24,Sheet3!A:E,1))+VLOOKUP(K24,Sheet3!A:E,3) -> 0.91261328 | P24: =IF(AND(O24>0.2,O24<0.7),"ok","bad") -> bad
A25: 07151211_1932 | B25: UMN | C25: 55 | D25: null | E25: 1000 | F25: 31 | G25: bg | H25: side 1: -3.999, side 2: 4.4872 | I25: good | J25: =""""&A25&"""" -> "07151211_1932" | K25: =DATE(2000+MID(A25,3,2),MID(A25,5,2),MID(A25,7,2))+TIME(MID(A25,10,2),MID(A25,12,2),0) -> 42349.814 | L25: =(K25-25569)*24*60 -> 24164372 | M25: np | N25: not sure | O25: =(VLOOKUP(K25,Sheet3!A:E,4)-VLOOKUP(K25,Sheet3!A:E,3))/(VLOOKUP(K25,Sheet3!A:E,2)-VLOOKUP(K25,Sheet3!A:E,1))*(K25-VLOOKUP(K25,Sheet3!A:E,1))+VLOOKUP(K25,Sheet3!A:E,3) -> 0.89725 | P25: =IF(AND(O25>0.2,O25<0.7),"ok","bad") -> bad
A26: 07151211_2125 | B26: UMN | C26: 55 | D26: null | E26: 1000 | F26: 31 | G26: bg | H26: side 1: -3.999, side 2: 4.4872 | I26: good | J26: =""""&A26&"""" -> "07151211_2125" | K26: =DATE(2000+MID(A26,3,2),MID(A26,5,2),MID(A26,7,2))+TIME(MID(A26,10,2),MID(A26,12,2),0) -> 42349.892 | L26: =(K26-25569)*24*60 -> 24164485 | M26: np | N26: not sure | O26: =(VLOOKUP(K26,Sheet3!A:E,4)-VLOOKUP(K26,Sheet3!A:E,3))/(VLOOKUP(K26,Sheet3!A:E,2)-VLOOKUP(K26,Sheet3!A:E,1))*(K26-VLOOKUP(K26,Sheet3!A:E,1))+VLOOKUP(K26,Sheet3!A:E,3) -> 0.86679297 | P26: =IF(AND(O26>0.2,O26<0.7),"ok","bad") -> bad
A27: 07151211_2222 | B27: UMN | C27: 55 | D27: null | E27: 1000 | F27: 31 | G27: bg | H27: side 1: -3.999, side 2: 4.4872 | I27: good | J27: =""""&A27&"""" -> "07151211_2222" | K27: =DATE(2000+MID(A27,3,2),MID(A27,5,2),MID(A27,7,2))+TIME(MID(A27,10,2),MID(A27,12,2),0) -> 42349.932 | L27: =(K27-25569)*24*60 -> 24164542 | M27: np | N27: not sure | O27: =(VLOOKUP(K27,Sheet3!A:E,4)-VLOOKUP(K27,Sheet3!A:E,3))/(VLOOKUP(K27,Sheet3!A:E,2)-VLOOKUP(K27,Sheet3!A:E,1))*(K27-VLOOKUP(K27,Sheet3!A:E,1))+VLOOKUP(K27,Sheet3!A:E,3) -> 0.85142969 | P27: =IF(AND(O27>0.2,O27<0.7),"ok","bad") -> bad
A28: 07151211_2318 | B28: UMN | C28: 55 | D28: null | E28: 1000 | F28: 31 | G28: bg | H28: side 1: -3.999, side 2: 4.4872 | I28: good | J28: =""""&A28&"""" -> "07151211_2318" | K28: =DATE(2000+MID(A28,3,2),MID(A28,5,2),MID(A28,7,2))+TIME(MID(A28,10,2),MID(A28,12,2),0) -> 42349.971 | L28: =(K28-25569)*24*60 -> 24164598 | M28: np | N28: not sure | O28: =(VLOOKUP(K28,Sheet3!A:E,4)-VLOOKUP(K28,Sheet3!A:E,3))/(VLOOKUP(K28,Sheet3!A:E,2)-VLOOKUP(K28,Sheet3!A:E,1))*(K28-VLOOKUP(K28,Sheet3!A:E,1))+VLOOKUP(K28,Sheet3!A:E,3) -> 0.83633594 | P28: =IF(AND(O28>0.2,O28<0.7),"ok","bad") -> bad
A29: 07151212_0112 | B29: UMN | C29: 55 | D29: null | E29: 1000 | F29: 31 | G29: bg | H29: side 1: -3.999, side 2: 4.4872 | I29: good | J29: =""""&A29&"""" -> "07151212_0112" | K29: =DATE(2000+MID(A29,3,2),MID(A29,5,2),MID(A29,7,2))+TIME(MID(A29,10,2),MID(A29,12,2),0) -> 42350.05 | L29: =(K29-25569)*24*60 -> 24164712 | M29: np | N29: not sure | O29: =(VLOOKUP(K29,Sheet3!A:E,4)-VLOOKUP(K29,Sheet3!A:E,3))/(VLOOKUP(K29,Sheet3!A:E,2)-VLOOKUP(K29,Sheet3!A:E,1))*(K29-VLOOKUP(K29,Sheet3!A:E,1))+VLOOKUP(K29,Sheet3!A:E,3) -> 0.80560937 | P29: =IF(AND(O29>0.2,O29<0.7),"ok","bad") -> bad
A30: 07151212_0208 | B30: UMN | C30: 55 | D30: null | E30: 1000 | F30: 31 | G30: bg | H30: side 1: -3.999, side 2: 4.4872 | I30: good | J30: =""""&A30&"""" -> "07151212_0208" | K30: =DATE(2000+MID(A30,3,2),MID(A30,5,2),MID(A30,7,2))+TIME(MID(A30,10,2),MID(A30,12,2),0) -> 42350.089 | L30: =(K30-25569)*24*60 -> 24164768 | M30: np | N30: not sure | O30: =(VLOOKUP(K30,Sheet3!A:E,4)-VLOOKUP(K30,Sheet3!A:E,3))/(VLOOKUP(K30,Sheet3!A:E,2)-VLOOKUP(K30,Sheet3!A:E,1))*(K30-VLOOKUP(K30,Sheet3!A:E,1))+VLOOKUP(K30,Sheet3!A:E,3) -> 0.79051563 | P30: =IF(AND(O30>0.2,O30<0.7),"ok","bad") -> bad
A31: 07151214_1704 | B31: UMN | C31: 55 | D31: null | E31: 1000 | F31: 31 | G31: bg | H31: side 1: 4.014, side 2: -3.9293 | I31: good | J31: =""""&A31&"""" -> "07151214_1704" | K31: =DATE(2000+MID(A31,3,2),MID(A31,5,2),MID(A31,7,2))+TIME(MID(A31,10,2),MID(A31,12,2),0) -> 42352.711 | L31: =(K31-25569)*24*60 -> 24168544 | M31: np | N31: wrong trace length | O31: =(VLOOKUP(K31,Sheet3!A:E,4)-VLOOKUP(K31,Sheet3!A:E,3))/(VLOOKUP(K31,Sheet3!A:E,2)-VLOOKUP(K31,Sheet3!A:E,1))*(K31-VLOOKUP(K31,Sheet3!A:E,1))+VLOOKUP(K31,Sheet3!A:E,3) -> 0.9029182 | P31: =IF(AND(O31>0.2,O31<0.7),"ok","bad") -> bad
A32: 07151214_1801 | B32: UMN | C32: 55 | D32: null | E32: 1000 | F32: 31 | G32: bg | H32: side 1: 4.014, side 2: -3.9293 | I32: good | J32: =""""&A32&"""" -> "07151214_1801" | K32: =DATE(2000+MID(A32,3,2),MID(A32,5,2),MID(A32,7,2))+TIME(MID(A32,10,2),MID(A32,12,2),0) -> 42352.751 | L32: =(K32-25569)*24*60 -> 24168601 | M32: np | N32: wrong trace length | O32: =(VLOOKUP(K32,Sheet3!A:E,4)-VLOOKUP(K32,Sheet3!A:E,3))/(VLOOKUP(K32,Sheet3!A:E,2)-VLOOKUP(K32,Sheet3!A:E,1))*(K32-VLOOKUP(K32,Sheet3!A:E,1))+VLOOKUP(K32,Sheet3!A:E,3) -> 0.88852249 | P32: =IF(AND(O32>0.2,O32<0.7),"ok","bad") -> bad
A33: 07151214_1858 | B33: UMN | C33: 55 | D33: null | E33: 1000 | F33: 31 | G33: bg | H33: side 1: 4.014, side 2: -3.9293 | I33: good | J33: =""""&A33&"""" -> "07151214_1858" | K33: =DATE(2000+MID(A33,3,2),MID(A33,5,2),MID(A33,7,2))+TIME(MID(A33,10,2),MID(A33,12,2),0) -> 42352.79 | L33: =(K33-25569)*24*60 -> 24168658 | M33: np | N33: wrong trace length | O33: =(VLOOKUP(K33,Sheet3!A:E,4)-VLOOKUP(K33,Sheet3!A:E,3))/(VLOOKUP(K33,Sheet3!A:E,2)-VLOOKUP(K33,Sheet3!A:E,1))*(K33-VLOOKUP(K33,Sheet3!A:E,1))+VLOOKUP(K33,Sheet3!A:E,3) -> 0.87412679 | P33: =IF(AND(O33>0.2,O33<0.7),"ok","bad") -> bad
A34: 07151214_1955 | B34: UMN | C34: 55 | D34: null | E34: 1000 | F34: 31 | G34: bg | H34: side 1: 4.014, side 2: -3.9293 | I34: good | J34: =""""&A34&"""" -> "07151214_1955" | K34: =DATE(2000+MID(A34,3,2),MID(A34,5,2),MID(A34,7,2))+TIME(MID(A34,10,2),MID(A34,12,2),0) -> 42352.83 | L34: =(K34-25569)*24*60 -> 24168715 | M34: np | N34: wrong trace length | O34: =(VLOOKUP(K34,Sheet3!A:E,4)-VLOOKUP(K34,Sheet3!A:E,3))/(VLOOKUP(K34,Sheet3!A:E,2)-VLOOKUP(K34,Sheet3!A:E,1))*(K34-VLOOKUP(K34,Sheet3!A:E,1))+VLOOKUP(K34,Sheet3!A:E,3) -> 0.85973108 | P34: =IF(AND(O34>0.2,O34<0.7),"ok","bad") -> bad
... A37: 07151214_2245 | B37: UMN | C37: 55 | D37: null | E37: 1000 | F37: 31 | G37: bg | H37: side 1: 4.014, side 2: -3.9293 | I37: good | J37: =""""&A37&"""" -> "07151214_2245" | K37: =DATE(2000+MID(A37,3,2),MID(A37,5,2),MID(A37,7,2))+TIME(MID(A37,10,2),MID(A37,12,2),0) -> 42352.948 | L37: =(K37-25569)*24*60 -> 24168885 | M37: np | N37: wrong trace length | O37: =(VLOOKUP(K37,Sheet3!A:E,4)-VLOOKUP(K37,Sheet3!A:E,3))/(VLOOKUP(K37,Sheet3!A:E,2)-VLOOKUP(K37,Sheet3!A:E,1))*(K37-VLOOKUP(K37,Sheet3!A:E,1))+VLOOKUP(K37,Sheet3!A:E,3) -> 0.81679652 | P37: =IF(AND(O37>0.2,O37<0.7),"ok","bad") -> bad
A38: 07151214_2341 | B38: UMN | C38: 55 | D38: null | E38: 1000 | F38: null | G38: bg | H38: side 1: 4.014, side 2: -3.9293 | I38: good | J38: =""""&A38&"""" -> "07151214_2341" | K38: =DATE(2000+MID(A38,3,2),MID(A38,5,2),MID(A38,7,2))+TIME(MID(A38,10,2),MID(A38,12,2),0) -> 42352.987 | L38: =(K38-25569)*24*60 -> 24168941 | M38: np | N38: wrong trace length | O38: =(VLOOKUP(K38,Sheet3!A:E,4)-VLOOKUP(K38,Sheet3!A:E,3))/(VLOOKUP(K38,Sheet3!A:E,2)-VLOOKUP(K38,Sheet3!A:E,1))*(K38-VLOOKUP(K38,Sheet3!A:E,1))+VLOOKUP(K38,Sheet3!A:E,3) -> 0.80265337 | P38: =IF(AND(O38>0.2,O38<0.7),"ok","bad") -> bad
A39: 07151218_0501 | B39: UMN | C39: 55 | D39: null | E39: 1000 | F39: 31 | G39: cf | H39: side 1: 4.014, side 2: -3.9293 | I39: good | J39: =""""&A39&"""" -> "07151218_0501" | K39: =DATE(2000+MID(A39,3,2),MID(A39,5,2),MID(A39,7,2))+TIME(MID(A39,10,2),MID(A39,12,2),0) -> 42356.209 | L39: =(K39-25569)*24*60 -> 24173581 | M39: np | O39: =(VLOOKUP(K39,Sheet3!A:E,4)-VLOOKUP(K39,Sheet3!A:E,3))/(VLOOKUP(K39,Sheet3!A:E,2)-VLOOKUP(K39,Sheet3!A:E,1))*(K39-VLOOKUP(K39,Sheet3!A:E,1))+VLOOKUP(K39,Sheet3!A:E,3) -> 0.13392797 | P39: =IF(AND(O39>0.2,O39<0.7),"ok","bad") -> bad
A40: 07151218_0557 | B40: UMN | C40: 55 | D40: null | E40: 1000 | F40: 31 | G40: cf | H40: side 1: 4.014, side 2: -3.9293 | I40: good | J40: =""""&A40&"""" -> "07151218_0557" | K40: =DATE(2000+MID(A40,3,2),MID(A40,5,2),MID(A40,7,2))+TIME(MID(A40,10,2),MID(A40,12,2),0) -> 42356.248 | L40: =(K40-25569)*24*60 -> 24173637 | M40: np | O40: =(VLOOKUP(K40,Sheet3!A:E,4)-VLOOKUP(K40,Sheet3!A:E,3))/(VLOOKUP(K40,Sheet3!A:E,2)-VLOOKUP(K40,Sheet3!A:E,1))*(K40-VLOOKUP(K40,Sheet3!A:E,1))+VLOOKUP(K40,Sheet3!A:E,3) -> 0.11660593 | P40: =IF(AND(O40>0.2,O40<0.7),"ok","bad") -> bad
A41: 07151218_0654 | B41: UMN | C41: 55 | D41: null | E41: 1000 | F41: 31 | G41: cf | H41: side 1: 4.014, side 2: -3.9293 | I41: good | J41: =""""&A41&"""" -> "07151218_0654" | K41: =DATE(2000+MID(A41,3,2),MID(A41,5,2),MID(A41,7,2))+TIME(MID(A41,10,2),MID(A41,12,2),0) -> 42356.287 | L41: =(K41-25569)*24*60 -> 24173694 | M41: np | O41: =(VLOOKUP(K41,Sheet3!A:E,4)-VLOOKUP(K41,Sheet3!A:E,3))/(VLOOKUP(K41,Sheet3!A:E,2)-VLOOKUP(K41,Sheet3!A:E,1))*(K41-VLOOKUP(K41,Sheet3!A:E,1))+VLOOKUP(K41,Sheet3!A:E,3) -> 0.098974576 | P41: =IF(AND(O41>0.2,O41<0.7),"ok","bad") -> bad
A42: 07151210_1319 | B42: UMN | C42: 55 | D42: null | E42: 1000 | F42: 10 | G42: bg | H42: side 1: -3.999, side 2: 4.4872 | I42: good | J42: =""""&A42&"""" -> "07151210_1319" | K42: =DATE(2000+MID(A42,3,2),MID(A42,5,2),MID(A42,7,2))+TIME(MID(A42,10,2),MID(A42,12,2),0) -> 42348.555 | L42: =(K42-25569)*24*60 -> 24162559 | M42: np | N42: short, not in run diary | O42: =(VLOOKUP(K42,Sheet3!A:E,4)-VLOOKUP(K42,Sheet3!A:E,3))/(VLOOKUP(K42,Sheet3!A:E,2)-VLOOKUP(K42,Sheet3!A:E,1))*(K42-VLOOKUP(K42,Sheet3!A:E,1))+VLOOKUP(K42,Sheet3!A:E,3) -> 0.623536 | P42: =IF(AND(O42>0.2,O42<0.7),"ok","bad") -> ok
A43: 07151211_1052 | B43: UMN | C43: 55 | D43: null | E43: 1000 | F43: 34 | G43: cf | H43: side 1: -3.999, side 2: 4.4872 | I43: good | J43: =""""&A43&"""" -> "07151211_1052" | K43: =DATE(2000+MID(A43,3,2),MID(A43,5,2),MID(A43,7,2))+TIME(MID(A43,10,2),MID(A43,12,2),0) -> 42349.453 | L43: =(K43-25569)*24*60 -> 24163852 | M43: np | N43: wrong trace length | O43: =(VLOOKUP(K43,Sheet3!A:E,4)-VLOOKUP(K43,Sheet3!A:E,3))/(VLOOKUP(K43,Sheet3!A:E,2)-VLOOKUP(K43,Sheet3!A:E,1))*(K43-VLOOKUP(K43,Sheet3!A:E,1))+VLOOKUP(K43,Sheet3!A:E,3) -> 0.4192987 | P43: =IF(AND(O43>0.2,O43<0.7),"ok","bad") -> ok
A44: 07151211_1151 | B44: UMN | C44: 55 | D44: null | E44: 1000 | F44: 34 | G44: cf | H44: side 1: -3.999, side 2: 4.4872 | I44: good | J44: =""""&A44&"""" -> "07151211_1151" | K44: =DATE(2000+MID(A44,3,2),MID(A44,5,2),MID(A44,7,2))+TIME(MID(A44,10,2),MID(A44,12,2),0) -> 42349.494 | L44: =(K44-25569)*24*60 -> 24163911 | M44: np | N44: wrong trace length | O44: =(VLOOKUP(K44,Sheet3!A:E,4)-VLOOKUP(K44,Sheet3!A:E,3))/(VLOOKUP(K44,Sheet3!A:E,2)-VLOOKUP(K44,Sheet3!A:E,1))*(K44-VLOOKUP(K44,Sheet3!A:E,1))+VLOOKUP(K44,Sheet3!A:E,3) -> 0.40090909 | P44: =IF(AND(O44>0.2,O44<0.7),"ok","bad") -> ok
A45: 07151211_1303 | B45: UMN | C45: 55 | D45: null | E45: 1000 | F45: 34 | G45: cf | H45: side 1: 4.014, side 2: -3.9293 | I45: good | J45: =""""&A45&"""" -> "07151211_1303" | K45: =DATE(2000+MID(A45,3,2),MID(A45,5,2),MID(A45,7,2))+TIME(MID(A45,10,2),MID(A45,12,2),0) -> 42349.544 | L45: =(K45-25569)*24*60 -> 24163983 | M45: np | N45: wrong trace length | O45: =(VLOOKUP(K45,Sheet3!A:E,4)-VLOOKUP(K45,Sheet3!A:E,3))/(VLOOKUP(K45,Sheet3!A:E,2)-VLOOKUP(K45,Sheet3!A:E,1))*(K45-VLOOKUP(K45,Sheet3!A:E,1))+VLOOKUP(K45,Sheet3!A:E,3) -> 0.37846753 | P45: =IF(AND(O45>0.2,O45<0.7),"ok","bad") -> ok
A46: 07151210_1644 | B46: UMN | C46: 55 | D46: null | E46: 1000 | F46: 4 | G46: bg | H46: side 1: -3.999, side 2: 4.4872 | I46: good | J46: =""""&A46&"""" -> "07151210_1644" | K46: =DATE(2000+MID(A46,3,2),MID(A46,5,2),MID(A46,7,2))+TIME(MID(A46,10,2),MID(A46,12,2),0) -> 42348.697 | L46: =(K46-25569)*24*60 -> 24162764 | M46: ok | N46: 0.77 | O46: =(VLOOKUP(K46,Sheet3!A:E,4)-VLOOKUP(K46,Sheet3!A:E,3))/(VLOOKUP(K46,Sheet3!A:E,2)-VLOOKUP(K46,Sheet3!A:E,1))*(K46-VLOOKUP(K46,Sheet3!A:E,1))+VLOOKUP(K46,Sheet3!A:E,3) -> 0.75263271 | P46: =IF(AND(O46>0.2,O46<0.7),"ok","bad") -> bad
A47: 07151211_1739 | B47: UMN | C47: 55 | D47: null | E47: 1000 | F47: 31 | G47: bg | H47: side 1: -3.999, side 2: 4.4872 | I47: good | J47: =""""&A47&"""" -> "07151211_1739" | K47: =DATE(2000+MID(A47,3,2),MID(A47,5,2),MID(A47,7,2))+TIME(MID(A47,10,2),MID(A47,12,2),0) -> 42349.735 | L47: =(K47-25569)*24*60 -> 24164259 | M47: ok | N47: 0.94 | O47: =(VLOOKUP(K47,Sheet3!A:E,4)-VLOOKUP(K47,Sheet3!A:E,3))/(VLOOKUP(K47,Sheet3!A:E,2)-VLOOKUP(K47,Sheet3!A:E,1))*(K47-VLOOKUP(K47,Sheet3!A:E,1))+VLOOKUP(K47,Sheet3!A:E,3) -> 0.92770703 | P47: =IF(AND(O47>0.2,O47<0.7),"ok","bad") -> bad
A48: 07151212_0305 | B48: UMN | C48: 55 | D48: null | E48: 1000 | F48: 31 | G48: bg | H48: side 1: -3.999, side 2: 4.4872 | I48: good | J48: =""""&A48&"""" -> "07151212_0305" | K48: =DATE(2000+MID(A48,3,2),MID(A48,5,2),MID(A48,7,2))+TIME(MID(A48,10,2),MID(A48,12,2),0) -> 42350.128 | L48: =(K48-25569)*24*60 -> 24164825 | M48: ok | N48: 0.77515234 | O48: =(VLOOKUP(K48,Sheet3!A:E,4)-VLOOKUP(K48,Sheet3!A:E,3))/(VLOOKUP(K48,Sheet3!A:E,2)-VLOOKUP(K48,Sheet3!A:E,1))*(K48-VLOOKUP(K48,Sheet3!A:E,1))+VLOOKUP(K48,Sheet3!A:E,3) -> 0.77515234 | P48: =IF(AND(O48>0.2,O48<0.7),"ok","bad") -> bad
A49: 07151212_0401 | B49: UMN | C49: 55 | D49: null | E49: 1000 | F49: 31 | G49: bg | H49: side 1: -3.999, side 2: 4.4872 | I49: good | J49: =""""&A49&"""" -> "07151212_0401" | K49: =DATE(2000+MID(A49,3,2),MID(A49,5,2),MID(A49,7,2))+TIME(MID(A49,10,2),MID(A49,12,2),0) -> 42350.167 | L49: =(K49-25569)*24*60 -> 24164881 | M49: ok | N49: 0.76005859 | O49: =(VLOOKUP(K49,Sheet3!A:E,4)-VLOOKUP(K49,Sheet3!A:E,3))/(VLOOKUP(K49,Sheet3!A:E,2)-VLOOKUP(K49,Sheet3!A:E,1))*(K49-VLOOKUP(K49,Sheet3!A:E,1))+VLOOKUP(K49,Sheet3!A:E,3) -> 0.76005859 | P49: =IF(AND(O49>0.2,O49<0.7),"ok","bad") -> bad
...

Sheet Sheet2
A4: series | B4: facility | C4: run number | D4: events per file | E4: randoms | F4: duration | G4: data type | H4: bias | I4: diagnosis | J4: seriesid string | K4: date/time | L4: list
A5: 07151208_1609 | B5: UMN | C5: 55 | D5: 2000 | E5: 1000 | F5: 30 | G5: bg | H5: side 1: -4, side 2: 4 | I5: good | J5: =""""&A5&"""" -> "07151208_1609" | K5: =DATE(2000+MID(A5,3,2),MID(A5,5,2),MID(A5,7,2))+TIME(MID(A5,10,2),MID(A5,12,2),0) -> 42346.673
A6: 07151208_1623 | B6: UMN | C6: 55 | D6: 2000 | E6: 1000 | F6: 30 | G6: bg | H6: side 1: -4, side 2: 4 | I6: good | J6: =""""&A6&"""" -> "07151208_1623" | K6: =DATE(2000+MID(A6,3,2),MID(A6,5,2),MID(A6,7,2))+TIME(MID(A6,10,2),MID(A6,12,2),0) -> 42346.683
A7: 07151208_1644 | B7: UMN | C7: 55 | D7: 2000 | E7: 1000 | F7: 30 | G7: bg | H7: side 1: -4, side 2: 4 | I7: good | J7: =""""&A7&"""" -> "07151208_1644" | K7: =DATE(2000+MID(A7,3,2),MID(A7,5,2),MID(A7,7,2))+TIME(MID(A7,10,2),MID(A7,12,2),0) -> 42346.697
A8: 07151208_1744 | B8: UMN | C8: 55 | D8: 2000 | E8: 1000 | F8: 30 | G8: bg | H8: side 1: 4, side 2: -4 | I8: good | J8: =""""&A8&"""" -> "07151208_1744" | K8: =DATE(2000+MID(A8,3,2),MID(A8,5,2),MID(A8,7,2))+TIME(MID(A8,10,2),MID(A8,12,2),0) -> 42346.739
A9: 07151208_1843 | B9: UMN | C9: 55 | D9: 2000 | E9: 1000 | F9: 30 | G9: bg | H9: side 1: -4, side 2: 4 | I9: good | J9: =""""&A9&"""" -> "07151208_1843" | K9: =DATE(2000+MID(A9,3,2),MID(A9,5,2),MID(A9,7,2))+TIME(MID(A9,10,2),MID(A9,12,2),0) -> 42346.78
A10: 07151208_1949 | B10: UMN | C10: 55 | D10: 2000 | E10: 1000 | F10: 30 | G10: bg | H10: side 1: 4, side 2: -4 | I10: good | J10: =""""&A10&"""" -> "07151208_1949" | K10: =DATE(2000+MID(A10,3,2),MID(A10,5,2),MID(A10,7,2))+TIME(MID(A10,10,2),MID(A10,12,2),0) -> 42346.826
A11: 07151208_2049 | B11: UMN | C11: 55 | D11: 2000 | E11: 1000 | F11: 30 | G11: bg | H11: side 1: -4, side 2: 4 | I11: good | J11: =""""&A11&"""" -> "07151208_2049" | K11: =DATE(2000+MID(A11,3,2),MID(A11,5,2),MID(A11,7,2))+TIME(MID(A11,10,2),MID(A11,12,2),0) -> 42346.867
A12: 07151208_2148 | B12: UMN | C12: 55 | D12: 2000 | E12: 1000 | F12: 30 | G12: bg | H12: side 1: 4, side 2: -4 | I12: good | J12: =""""&A12&"""" -> "07151208_2148" | K12: =DATE(2000+MID(A12,3,2),MID(A12,5,2),MID(A12,7,2))+TIME(MID(A12,10,2),MID(A12,12,2),0) -> 42346.908
A13: 07151208_2248 | B13: UMN | C13: 55 | D13: 2000 | E13: 1000 | F13: 30 | G13: bg | H13: side 1: -4, side 2: 4 | I13: good | J13: =""""&A13&"""" -> "07151208_2248" | K13: =DATE(2000+MID(A13,3,2),MID(A13,5,2),MID(A13,7,2))+TIME(MID(A13,10,2),MID(A13,12,2),0) -> 42346.95
A14: 07151208_2348 | B14: UMN | C14: 55 | D14: 2000 | E14: 1000 | F14: 30 | G14: bg | H14: side 1: 4, side 2: -4 | I14: good | J14: =""""&A14&"""" -> "07151208_2348" | K14: =DATE(2000+MID(A14,3,2),MID(A14,5,2),MID(A14,7,2))+TIME(MID(A14,10,2),MID(A14,12,2),0) -> 42346.992
A15: 07151209_0048 | B15: UMN | C15: 55 | D15: 2000 | E15: 1000 | F15: 30 | G15: bg | H15: side 1: -4, side 2: 4 | I15: good | J15: =""""&A15&"""" -> "07151209_0048" | K15: =DATE(2000+MID(A15,3,2),MID(A15,5,2),MID(A15,7,2))+TIME(MID(A15,10,2),MID(A15,12,2),0) -> 42347.033
A16: 07151209_0147 | B16: UMN | C16: 55 | D16: 2000 | E16: 1000 | F16: 30 | G16: bg | H16: side 1: 4, side 2: -4 | I16: good | J16: =""""&A16&"""" -> "07151209_0147" | K16: =DATE(2000+MID(A16,3,2),MID(A16,5,2),MID(A16,7,2))+TIME(MID(A16,10,2),MID(A16,12,2),0) -> 42347.074
... A22: 07151209_0750 | B22: UMN | C22: 55 | D22: 2000 | E22: 1000 | F22: 30 | G22: bg | H22: side 1: 4, side 2: -4 | I22: good | J22: =""""&A22&"""" -> "07151209_0750" | K22: =DATE(2000+MID(A22,3,2),MID(A22,5,2),MID(A22,7,2))+TIME(MID(A22,10,2),MID(A22,12,2),0) -> 42347.326
A23: 07151209_1516 | B23: UMN | C23: 55 | D23: null | E23: 1000 | F23: 31 | G23: bg | H23: side 1: -3.999, side 2: 4.4872 | I23: good | J23: =""""&A23&"""" -> "07151209_1516" | K23: =DATE(2000+MID(A23,3,2),MID(A23,5,2),MID(A23,7,2))+TIME(MID(A23,10,2),MID(A23,12,2),0) -> 42347.636
A24: 07151209_1613 | B24: UMN | C24: 55 | D24: null | E24: 1000 | F24: 31 | G24: bg | H24: side 1: -3.999, side 2: 4.4872 | I24: good | J24: =""""&A24&"""" -> "07151209_1613" | K24: =DATE(2000+MID(A24,3,2),MID(A24,5,2),MID(A24,7,2))+TIME(MID(A24,10,2),MID(A24,12,2),0) -> 42347.676
A25: 07151209_1728 | B25: UMN | C25: 55 | D25: null | E25: 1000 | F25: 31 | G25: bg | H25: side 1: -3.999, side 2: 4.4872 | I25: good | J25: =""""&A25&"""" -> "07151209_1728" | K25: =DATE(2000+MID(A25,3,2),MID(A25,5,2),MID(A25,7,2))+TIME(MID(A25,10,2),MID(A25,12,2),0) -> 42347.728
A26: 07151209_1824 | B26: UMN | C26: 55 | D26: null | E26: 1000 | F26: 31 | G26: bg | H26: side 1: -3.999, side 2: 4.4872 | I26: good | J26: =""""&A26&"""" -> "07151209_1824" | K26: =DATE(2000+MID(A26,3,2),MID(A26,5,2),MID(A26,7,2))+TIME(MID(A26,10,2),MID(A26,12,2),0) -> 42347.767
A27: 07151209_1921 | B27: UMN | C27: 55 | D27: null | E27: 1000 | F27: 31 | G27: bg | H27: side 1: -3.999, side 2: 4.4872 | I27: good | J27: =""""&A27&"""" -> "07151209_1921" | K27: =DATE(2000+MID(A27,3,2),MID(A27,5,2),MID(A27,7,2))+TIME(MID(A27,10,2),MID(A27,12,2),0) -> 42347.806
A28: 07151209_2018 | B28: UMN | C28: 55 | D28: null | E28: 1000 | F28: 31 | G28: bg | H28: side 1: -3.999, side 2: 4.4872 | I28: good | J28: =""""&A28&"""" -> "07151209_2018" | K28: =DATE(2000+MID(A28,3,2),MID(A28,5,2),MID(A28,7,2))+TIME(MID(A28,10,2),MID(A28,12,2),0) -> 42347.846
A29: 07151209_2114 | B29: UMN | C29: 55 | D29: null | E29: 1000 | F29: 31 | G29: bg | H29: side 1: -3.999, side 2: 4.4872 | I29: good | J29: =""""&A29&"""" -> "07151209_2114" | K29: =DATE(2000+MID(A29,3,2),MID(A29,5,2),MID(A29,7,2))+TIME(MID(A29,10,2),MID(A29,12,2),0) -> 42347.885
A30: 07151209_2211 | B30: UMN | C30: 55 | D30: null | E30: 1000 | F30: 31 | G30: bg | H30: side 1: -3.999, side 2: 4.4872 | I30: good | J30: =""""&A30&"""" -> "07151209_2211" | K30: =DATE(2000+MID(A30,3,2),MID(A30,5,2),MID(A30,7,2))+TIME(MID(A30,10,2),MID(A30,12,2),0) -> 42347.924
A31: 07151209_2308 | B31: UMN | C31: 55 | D31: null | E31: 1000 | F31: 31 | G31: bg | H31: side 1: -3.999, side 2: 4.4872 | I31: good | J31: =""""&A31&"""" -> "07151209_2308" | K31: =DATE(2000+MID(A31,3,2),MID(A31,5,2),MID(A31,7,2))+TIME(MID(A31,10,2),MID(A31,12,2),0) -> 42347.964
A32: 07151210_0005 | B32: UMN | C32: 55 | D32: null | E32: 1000 | F32: 31 | G32: bg | H32: side 1: -3.999, side 2: 4.4872 | I32: good | J32: =""""&A32&"""" -> "07151210_0005" | K32: =DATE(2000+MID(A32,3,2),MID(A32,5,2),MID(A32,7,2))+TIME(MID(A32,10,2),MID(A32,12,2),0) -> 42348.003
A33: 07151210_0101 | B33: UMN | C33: 55 | D33: null | E33: 1000 | F33: 31 | G33: bg | H33: side 1: -3.999, side 2: 4.4872 | I33: good | J33: =""""&A33&"""" -> "07151210_0101" | K33: =DATE(2000+MID(A33,3,2),MID(A33,5,2),MID(A33,7,2))+TIME(MID(A33,10,2),MID(A33,12,2),0) -> 42348.042
A34: 07151210_0158 | B34: UMN | C34: 55 | D34: null | E34: 1000 | F34: 31 | G34: bg | H34: side 1: -3.999, side 2: 4.4872 | I34: good | J34: =""""&A34&"""" -> "07151210_0158" | K34: =DATE(2000+MID(A34,3,2),MID(A34,5,2),MID(A34,7,2))+TIME(MID(A34,10,2),MID(A34,12,2),0) -> 42348.082
... A91: 07151212_2351 | B91: UMN | C91: 55 | D91: null | E91: 1000 | F91: 31 | G91: bg | H91: side 1: -3.999, side 2: 4.4872 | I91: good | J91: =""""&A91&"""" -> "07151212_2351" | K91: =DATE(2000+MID(A91,3,2),MID(A91,5,2),MID(A91,7,2))+TIME(MID(A91,10,2),MID(A91,12,2),0) -> 42350.994
A92: 07151213_0047 | B92: UMN | C92: 55 | D92: null | E92: 1000 | F92: null | G92: bg | H92: side 1: -3.999, side 2: 4.4872 | I92: good | J92: =""""&A92&"""" -> "07151213_0047" | K92: =DATE(2000+MID(A92,3,2),MID(A92,5,2),MID(A92,7,2))+TIME(MID(A92,10,2),MID(A92,12,2),0) -> 42351.033
A93: 07151214_1207 | B93: UMN | C93: 55 | D93: null | E93: 1000 | F93: 31 | G93: bg | H93: side 1: 4.014, side 2: -3.9293 | I93: good | J93: =""""&A93&"""" -> "07151214_1207" | K93: =DATE(2000+MID(A93,3,2),MID(A93,5,2),MID(A93,7,2))+TIME(MID(A93,10,2),MID(A93,12,2),0) -> 42352.505
A94: 07151214_1704 | B94: UMN | C94: 55 | D94: null | E94: 1000 | F94: 31 | G94: bg | H94: side 1: 4.014, side 2: -3.9293 | I94: good | J94: =""""&A94&"""" -> "07151214_1704" | K94: =DATE(2000+MID(A94,3,2),MID(A94,5,2),MID(A94,7,2))+TIME(MID(A94,10,2),MID(A94,12,2),0) -> 42352.711
A95: 07151214_1801 | B95: UMN | C95: 55 | D95: null | E95: 1000 | F95: 31 | G95: bg | H95: side 1: 4.014, side 2: -3.9293 | I95: good | J95: =""""&A95&"""" -> "07151214_1801" | K95: =DATE(2000+MID(A95,3,2),MID(A95,5,2),MID(A95,7,2))+TIME(MID(A95,10,2),MID(A95,12,2),0) -> 42352.751
A96: 07151214_1858 | B96: UMN | C96: 55 | D96: null | E96: 1000 | F96: 31 | G96: bg | H96: side 1: 4.014, side 2: -3.9293 | I96: good | J96: =""""&A96&"""" -> "07151214_1858" | K96: =DATE(2000+MID(A96,3,2),MID(A96,5,2),MID(A96,7,2))+TIME(MID(A96,10,2),MID(A96,12,2),0) -> 42352.79
A97: 07151214_1955 | B97: UMN | C97: 55 | D97: null | E97: 1000 | F97: 31 | G97: bg | H97: side 1: 4.014, side 2: -3.9293 | I97: good | J97: =""""&A97&"""" -> "07151214_1955" | K97: =DATE(2000+MID(A97,3,2),MID(A97,5,2),MID(A97,7,2))+TIME(MID(A97,10,2),MID(A97,12,2),0) -> 42352.83
A98: 07151214_2051 | B98: UMN | C98: 55 | D98: null | E98: 1000 | F98: 31 | G98: bg | H98: side 1: 4.014, side 2: -3.9293 | I98: good | J98: =""""&A98&"""" -> "07151214_2051" | K98: =DATE(2000+MID(A98,3,2),MID(A98,5,2),MID(A98,7,2))+TIME(MID(A98,10,2),MID(A98,12,2),0) -> 42352.869
A99: 07151214_2148 | B99: UMN | C99: 55 | D99: null | E99: 1000 | F99: 31 | G99: bg | H99: side 1: 4.014, side 2: -3.9293 | I99: good | J99: =""""&A99&"""" -> "07151214_2148" | K99: =DATE(2000+MID(A99,3,2),MID(A99,5,2),MID(A99,7,2))+TIME(MID(A99,10,2),MID(A99,12,2),0) -> 42352.908
A100: 07151214_2245 | B100: UMN | C100: 55 | D100: null | E100: 1000 | F100: 31 | G100: bg | H100: side 1: 4.014, side 2: -3.9293 | I100: good | J100: =""""&A100&"""" -> "07151214_2245" | K100: =DATE(2000+MID(A100,3,2),MID(A100,5,2),MID(A100,7,2))+TIME(MID(A100,10,2),MID(A100,12,2),0) -> 42352.948
A101: 07151214_2341 | B101: UMN | C101: 55 | D101: null | E101: 1000 | F101: null | G101: bg | H101: side 1: 4.014, side 2: -3.9293 | I101: good | J101: =""""&A101&"""" -> "07151214_2341" | K101: =DATE(2000+MID(A101,3,2),MID(A101,5,2),MID(A101,7,2))+TIME(MID(A101,10,2),MID(A101,12,2),0) -> 42352.987
A102: 07151215_1146 | B102: UMN | C102: 55 | D102: null | E102: 0 | F102: 2 | G102: bg | H102: side 1: 0, side 2: 0 | I102: good | J102: =""""&A102&"""" -> "07151215_1146" | K102: =DATE(2000+MID(A102,3,2),MID(A102,5,2),MID(A102,7,2))+TIME(MID(A102,10,2),MID(A102,12,2),0) -> 42353.49
A103: 07151215_1147 | B103: UMN | C103: 55 | D103: null | E103: 0 | F103: 1 | G103: bg | H103: side 1: 0, side 2: 0 | I103: good | J103: =""""&A103&"""" -> "07151215_1147" | K103: =DATE(2000+MID(A103,3,2),MID(A103,5,2),MID(A103,7,2))+TIME(MID(A103,10,2),MID(A103,12,2),0) -> 42353.491
A104: 07151215_1231 | B104: UMN | C104: 55 | D104: null | E104: 1000 | F104: 31 | G104: bg | H104: side 1: 4.014, side 2: -3.9293 | I104: good | J104: =""""&A104&"""" -> "07151215_1231" | K104: =DATE(2000+MID(A104,3,2),MID(A104,5,2),MID(A104,7,2))+TIME(MID(A104,10,2),MID(A104,12,2),0) -> 42353.522
...

Sheet Sheet3
A1: 42341.347 | B1: =A2 -> 42341.5 | C1: 0.365 | D1: =C2 -> 0.295 | E1: 1
A2: 42341.5 | B2: =A3 -> 42341.653 | C2: 0.295 | D2: =C3 -> 0.931 | E2: 2 | N2: 16.5 | O2: =N2*8928/2 -> 73656 | P2: =N2*3824/2 -> 31548
A3: 42341.653 | B3: =A4 -> 42342.382 | C3: 0.931 | D3: =C4 -> 0.71 | E3: 3 | N3: 19.95 | O3: =N3*8928/2 -> 89056.8 | P3: =N3*3824/2 -> 38144.4
A4: 42342.382 | B4: =A5 -> 42342.483 | C4: 0.71 | D4: =C5 -> 0.671 | E4: 4
A5: 42342.483 | B5: =A6 -> 42342.67 | C5: 0.671 | D5: =C6 -> 0.604 | E5: 5
A6: 42342.67 | B6: =A7 -> 42343.59 | C6: 0.604 | D6: =C7 -> 0.269 | E6: 6
A7: 42343.59 | B7: =A8 -> 42343.645 | C7: 0.269 | D7: =C8 -> 0.908 | E7: 7
A8: 42343.645 | B8: =A9 -> 42344.712 | C8: 0.908 | D8: =C9 -> 0.463 | E8: 8
A9: 42344.712 | B9: =A10 -> 42345.361 | C9: 0.463 | D9: =C10 -> 0.153 | E9: 9
A10: 42345.361 | B10: =A11 -> 42345.41 | C10: 0.153 | D10: =C11 -> 0.645 | E10: 10
A11: 42345.41 | B11: =A12 -> 42346.344 | C11: 0.645 | D11: =C12 -> 0.24 | E11: 11
A12: 42346.344 | B12: =A13 -> 42346.412 | C12: 0.24 | D12: =C13 -> 0.904 | E12: 12
A13: 42346.412 | B13: =A14 -> 42346.671 | C13: 0.904 | D13: =C14 -> 0.838 | E13: 13
A14: 42346.671 | B14: =A15 -> 42347.365 | C14: 0.838 | D14: =C15 -> 0.647 | E14: 14
A15: 42347.365 | B15: =A16 -> 42348.344 | C15: 0.647 | D15: =C16 -> 0.327 | E15: 15
... A35: 42355.719 | B35: =A36 -> 42356.375 | C35: 0.352 | D35: =C36 -> 0.06 | E35: 35
A36: 42356.375 | C36: 0.06 | E36: 36

Sheet Run56
A2: SERIES | B2: FACILITY | C2: RUN NUMBER | D2: EVENTS PER FILE | E2: RANDOMS | F2: DURATION | G2: DATA TYPE | H2: BIAS | I2: DIAGNOSIS | J2: my diag | K2: lev diag | L2: date/time | M2: notes | N2: level | O2: level meas | P2: lev meas time | Q2: boiloff rate | R2: lev after | S2: lev time after | AD2: pbs1
A3: 07160104_1511 | B3: UMN | C3: 56 | D3: null | E3: 1000 | F3: 31 | G3: cf | H3: side 1: -3.999, side 2: 4.4872 | I3: good | J3: ok | K3: =IF(AND(N3<0.7,N3>0.2),"lev OK","lev BAD") -> lev OK | L3: =DATE(2000+MID(A3,3,2),MID(A3,5,2),MID(A3,7,2))+TIME(MID(A3,10,2),MID(A3,12,2),0) -> 42373.633 | M3: single | N3: =O3-(L3-P3)*24*Q3 -> 0.65486418 | O3: 0.714 | P3: 42373.438 | Q3: =(O3-R3)/(S3-P3)/24 -> 0.012626866 | R3: 0.432 | S3: 42374.368 | AC3: 1.57142e-10 | AD3: 1.20965e-10 | AE3: 1.34184e-10 | AF3: 9.86085e-11 | AG3: 1.64078e-10 | AH3: 1.7321e-10 | AI3: 8.00181e-11 | AJ3: 1.78576e-10 | AK3: 8.4009e-11 | AL3: 1.5693e-10 | AM3: 1.43373e-10 | AN3: 1.73664e-10
A4: 07160104_1614 | B4: UMN | C4: 56 | D4: null | E4: 1000 | F4: 31 | G4: cf | H4: side 1: 4.014, side 2: -3.9293 | I4: good | J4: ok | K4: =IF(AND(N4<0.7,N4>0.2),"lev OK","lev BAD") -> lev OK | L4: =DATE(2000+MID(A4,3,2),MID(A4,5,2),MID(A4,7,2))+TIME(MID(A4,10,2),MID(A4,12,2),0) -> 42373.676 | M4: single | N4: =O4-(L4-P4)*24*Q4 -> 0.64160597 | O4: 0.714 | P4: 42373.438 | Q4: =Q3 -> 0.012626866 | AC4: 1.10173e-10 | AD4: 7.95169e-11 | AE4: 9.45369e-11 | AF4: 6.80599e-11 | AG4: 1.05499e-10 | AH4: 1.02812e-10 | AI4: 5.68269e-11 | AJ4: 1.2336e-10 | AK4: 7.17762e-11 | AL4: 1.07485e-10 | AM4: 9.85408e-11 | AN4: 7.25735e-11
A5: 07160104_1726 | B5: UMN | C5: 56 | D5: null | E5: 1000 | F5: 31 | G5: cf | H5: side 1: 4.014, side 2: -3.929 | I5: good | J5: ok | K5: =IF(AND(N5<0.7,N5>0.2),"lev OK","lev BAD") -> lev OK | L5: =DATE(2000+MID(A5,3,2),MID(A5,5,2),MID(A5,7,2))+TIME(MID(A5,10,2),MID(A5,12,2),0) -> 42373.726 | M5: block 1 | N5: =O5-(L5-P5)*24*Q5 -> 0.62645373 | O5: 0.714 | P5: 42373.438 | Q5: =Q4 -> 0.012626866 | AC5: 7.97431e-11 | AD5: 5.96412e-11 | AE5: 6.94847e-11 | AF5: 4.94649e-11 | AG5: 9.2614e-11 | AH5: 7.98004e-11 | AI5: 4.28249e-11 | AJ5: 9.51269e-11 | AK5: 4.42318e-11 | AL5: 7.73465e-11 | AM5: 7.4241e-11 | AN5: 5.68363e-11
A6: 07160104_1822 | B6: UMN | C6: 56 | D6: null | E6: 1000 | F6: 31 | G6: cf | H6: side 1: 4.014, side 2: -3.929 | I6: good | J6: ok | K6: =IF(AND(N6<0.7,N6>0.2),"lev OK","lev BAD") -> lev OK | L6: =DATE(2000+MID(A6,3,2),MID(A6,5,2),MID(A6,7,2))+TIME(MID(A6,10,2),MID(A6,12,2),0) -> 42373.765 | M6: block 1 | N6: =O6-(L6-P6)*24*Q6 -> 0.61466866 | O6: 0.714 | P6: 42373.438 | Q6: =Q5 -> 0.012626866 | AC6: 8.00007e-11 | AD6: 6.52519e-11 | AE6: 8.03568e-11 | AF6: 4.92034e-11 | AG6: 8.7527e-11 | AH6: 7.33175e-11 | AI6: 4.44709e-11 | AJ6: 9.67283e-11 | AK6: 4.48083e-11 | AL6: 8.48559e-11 | AM6: 7.36099e-11 | AN6: 5.58965e-11
A7: 07160104_1919 | B7: UMN | C7: 56 | D7: null | E7: 1000 | F7: 31 | G7: cf | H7: side 1: 4.014, side 2: -3.929 | I7: good | J7: ok | K7: =IF(AND(N7<0.7,N7>0.2),"lev OK","lev BAD") -> lev OK | L7: =DATE(2000+MID(A7,3,2),MID(A7,5,2),MID(A7,7,2))+TIME(MID(A7,10,2),MID(A7,12,2),0) -> 42373.805 | M7: block 1 | N7: =O7-(L7-P7)*24*Q7 -> 0.60267313 | O7: 0.714 | P7: 42373.438 | Q7: =Q6 -> 0.012626866 | AC7: 6.2179e-11 | AD7: 4.86811e-11 | AE7: 5.48535e-11 | AF7: 3.90895e-11 | AG7: 7.41046e-11 | AH7: 6.04857e-11 | AI7: 3.62911e-11 | AJ7: 7.68152e-11 | AK7: 3.69064e-11 | AL7: 7.02935e-11 | AM7: 5.73093e-11 | AN7: 4.84849e-11
A8: 07160104_2016 | B8: UMN | C8: 56 | D8: null | E8: 1000 | F8: 31 | G8: cf | H8: side 1: 4.014, side 2: -3.929 | I8: good | J8: ok | K8: =IF(AND(N8<0.7,N8>0.2),"lev OK","lev BAD") -> lev OK | L8: =DATE(2000+MID(A8,3,2),MID(A8,5,2),MID(A8,7,2))+TIME(MID(A8,10,2),MID(A8,12,2),0) -> 42373.844 | M8: block 1 | N8: =O8-(L8-P8)*24*Q8 -> 0.59067761 | O8: 0.714 | P8: 42373.438 | Q8: =Q7 -> 0.012626866 | AC8: 9.59915e-11 | AD8: 7.47314e-11 | AE8: 8.60905e-11 | AF8: 6.06243e-11 | AG8: 1.02881e-10 | AH8: 8.9496e-11 | AI8: 5.26852e-11 | AJ8: 1.19557e-10 | AK8: 5.12727e-11 | AL8: 9.70152e-11 | AM8: 8.8991e-11 | AN8: 6.78354e-11
A9: 07160104_2112 | B9: UMN | C9: 56 | D9: null | E9: 1000 | F9: 31 | G9: cf | H9: side 1: 4.014, side 2: -3.929 | I9: good | J9: ok | K9: =IF(AND(N9<0.7,N9>0.2),"lev OK","lev BAD") -> lev OK | L9: =DATE(2000+MID(A9,3,2),MID(A9,5,2),MID(A9,7,2))+TIME(MID(A9,10,2),MID(A9,12,2),0) -> 42373.883 | M9: block 1 | N9: =O9-(L9-P9)*24*Q9 -> 0.57889254 | O9: 0.714 | P9: 42373.438 | Q9: =Q8 -> 0.012626866 | AC9: 6.74883e-11 | AD9: 5.15771e-11 | AE9: 6.46161e-11 | AF9: 4.4321e-11 | AG9: 7.77981e-11 | AH9: 7.04701e-11 | AI9: 3.8241e-11 | AJ9: 8.79103e-11 | AK9: 4.15392e-11 | AL9: 7.3191e-11 | AM9: 6.48827e-11 | AN9: 5.37425e-11
A10: 07160104_2209 | B10: UMN | C10: 56 | D10: null | E10: 1000 | F10: 31 | G10: cf | H10: side 1: 4.014, side 2: -3.929 | I10: good | J10: ok | K10: =IF(AND(N10<0.7,N10>0.2),"lev OK","lev BAD") -> lev OK | L10: =DATE(2000+MID(A10,3,2),MID(A10,5,2),MID(A10,7,2))+TIME(MID(A10,10,2),MID(A10,12,2),0) -> 42373.923 | M10: block 1 | N10: =O10-(L10-P10)*24*Q10 -> 0.56689701 | O10: 0.714 | P10: 42373.438 | Q10: =Q9 -> 0.012626866 | AC10: 6.06483e-11 | AD10: 4.58735e-11 | AE10: 5.67046e-11 | AF10: 3.89315e-11 | AG10: 7.4728e-11 | AH10: 6.42099e-11 | AI10: 3.62252e-11 | AJ10: 7.52329e-11 | AK10: 3.9933e-11 | AL10: 6.49254e-11 | AM10: 5.81474e-11 | AN10: 4.93821e-11
A11: 07160104_2306 | B11: UMN | C11: 56 | D11: null | E11: 1000 | F11: 31 | G11: cf | H11: side 1: 4.014, side 2: -3.929 | I11: good | J11: ok | K11: =IF(AND(N11<0.7,N11>0.2),"lev OK","lev BAD") -> lev OK | L11: =DATE(2000+MID(A11,3,2),MID(A11,5,2),MID(A11,7,2))+TIME(MID(A11,10,2),MID(A11,12,2),0) -> 42373.963 | M11: block 1 | N11: =O11-(L11-P11)*24*Q11 -> 0.55490149 | O11: 0.714 | P11: 42373.438 | Q11: =Q10 -> 0.012626866 | AC11: 5.87239e-11 | AD11: 4.39084e-11 | AE11: 5.28252e-11 | AF11: 3.83924e-11 | AG11: 6.5002e-11 | AH11: 6.57852e-11 | AI11: 3.47502e-11 | AJ11: 7.40315e-11 | AK11: 3.56514e-11 | AL11: 6.27472e-11 | AM11: 5.33188e-11 | AN11: 4.72137e-11
A12: 07160105_0002 | B12: UMN | C12: 56 | D12: null | E12: 1000 | F12: 31 | G12: cf | H12: side 1: 4.014, side 2: -3.929 | I12: good | J12: ok | K12: =IF(AND(N12<0.7,N12>0.2),"lev OK","lev BAD") -> lev OK | L12: =DATE(2000+MID(A12,3,2),MID(A12,5,2),MID(A12,7,2))+TIME(MID(A12,10,2),MID(A12,12,2),0) -> 42374.001 | M12: block 1 | N12: =O12-(L12-P12)*24*Q12 -> 0.54311642 | O12: 0.714 | P12: 42373.438 | Q12: =Q11 -> 0.012626866 | AC12: 7.60128e-11 | AD12: 5.36989e-11 | AE12: 6.55116e-11 | AF12: 4.92258e-11 | AG12: 8.04166e-11 | AH12: 7.52796e-11 | AI12: 4.34786e-11 | AJ12: 9.39258e-11 | AK12: 4.37875e-11 | AL12: 7.43822e-11 | AM12: 6.83739e-11 | AN12: 5.54267e-11
A13: 07160105_0059 | B13: UMN | C13: 56 | D13: null | E13: 1000 | F13: 31 | G13: cf | H13: side 1: 4.014, side 2: -3.929 | I13: good | J13: ok | K13: =IF(AND(N13<0.7,N13>0.2),"lev OK","lev BAD") -> lev OK | L13: =DATE(2000+MID(A13,3,2),MID(A13,5,2),MID(A13,7,2))+TIME(MID(A13,10,2),MID(A13,12,2),0) -> 42374.041 | M13: block 1 | N13: =O13-(L13-P13)*24*Q13 -> 0.5311209 | O13: 0.714 | P13: 42373.438 | Q13: =Q12 -> 0.012626866 | AC13: 7.27977e-11 | AD13: 5.17166e-11 | AE13: 6.40461e-11 | AF13: 4.62166e-11 | AG13: 7.94214e-11 | AH13: 6.82621e-11 | AI13: 4.21785e-11 | AJ13: 9.10672e-11 | AK13: 4.40635e-11 | AL13: 7.2834e-11 | AM13: 6.49254e-11 | AN13: 5.64584e-11
A14: 07160105_0156 | B14: UMN | C14: 56 | D14: null | E14: 1000 | F14: 31 | G14: cf | H14: side 1: 4.014, side 2: -3.929 | I14: good | J14: ok | K14: =IF(AND(N14<0.7,N14>0.2),"lev OK","lev BAD") -> lev OK | L14: =DATE(2000+MID(A14,3,2),MID(A14,5,2),MID(A14,7,2))+TIME(MID(A14,10,2),MID(A14,12,2),0) -> 42374.081 | M14: block 1 | N14: =O14-(L14-P14)*24*Q14 -> 0.51912537 | O14: 0.714 | P14: 42373.438 | Q14: =Q13 -> 0.012626866 | AC14: 8.40343e-11 | AD14: 5.93707e-11 | AE14: 6.78224e-11 | AF14: 5.23166e-11 | AG14: 8.48623e-11 | AH14: 8.62212e-11 | AI14: 4.75039e-11 | AJ14: 1.04931e-10 | AK14: 4.47488e-11 | AL14: 7.98953e-11 | AM14: 7.29852e-11 | AN14: 6.28459e-11
A15: 07160105_0253 | B15: UMN | C15: 56 | D15: null | E15: 1000 | F15: 31 | G15: cf | H15: side 1: 4.014, side 2: -3.929 | I15: good | J15: ok | K15: =IF(AND(N15<0.7,N15>0.2),"lev OK","lev BAD") -> lev OK | L15: =DATE(2000+MID(A15,3,2),MID(A15,5,2),MID(A15,7,2))+TIME(MID(A15,10,2),MID(A15,12,2),0) -> 42374.12 | M15: block 1 | N15: =O15-(L15-P15)*24*Q15 -> 0.50712985 | O15: 0.714 | P15: 42373.438 | Q15: =Q14 -> 0.012626866 | AC15: 6.07117e-11 | AD15: 4.43273e-11 | AE15: 5.0198e-11 | AF15: 3.85204e-11 | AG15: 6.76901e-11 | AH15: 6.01678e-11 | AI15: 3.42647e-11 | AJ15: 7.27578e-11 | AK15: 3.70411e-11 | AL15: 6.16659e-11 | AM15: 5.20336e-11 | AN15: 4.53822e-11
... A17: 07160105_0446 | B17: UMN | C17: 56 | D17: null | E17: 1000 | F17: 31 | G17: cf | H17: side 1: 4.014, side 2: -3.929 | I17: good | J17: ok | K17: =IF(AND(N17<0.7,N17>0.2),"lev OK","lev BAD") -> lev OK | L17: =DATE(2000+MID(A17,3,2),MID(A17,5,2),MID(A17,7,2))+TIME(MID(A17,10,2),MID(A17,12,2),0) -> 42374.199 | M17: block 1 | N17: =O17-(L17-P17)*24*Q17 -> 0.48334925 | O17: 0.714 | P17: 42373.438 | Q17: =Q16 -> 0.012626866 | AC17: 5.08615e-11 | AD17: 3.65627e-11 | AE17: 4.35204e-11 | AF17: 3.33236e-11 | AG17: 4.93447e-11 | AH17: 5.23693e-11 | AI17: 2.64025e-11 | AJ17: 5.98866e-11 | AK17: 3.31634e-11 | AL17: 5.15639e-11 | AM17: 4.31827e-11 | AN17: 3.51074e-11
A18: 07160105_0543 | B18: UMN | C18: 56 | D18: null | E18: 1000 | F18: 31 | G18: cf | H18: side 1: 4.014, side 2: -3.929 | I18: good | J18: ok | K18: =IF(AND(N18<0.7,N18>0.2),"lev OK","lev BAD") -> lev OK | L18: =DATE(2000+MID(A18,3,2),MID(A18,5,2),MID(A18,7,2))+TIME(MID(A18,10,2),MID(A18,12,2),0) -> 42374.238 | M18: block 1 | N18: =O18-(L18-P18)*24*Q18 -> 0.47135373 | O18: 0.714 | P18: 42373.438 | Q18: =Q17 -> 0.012626866 | Z18: 161 | AA18: 46 | AC18: 6.20706e-11 | AD18: 4.19152e-11 | AE18: 5.12213e-11 | AF18: 4.15857e-11 | AG18: 5.41681e-11 | AH18: 6.39105e-11 | AI18: 3.62599e-11 | AJ18: 7.46761e-11 | AK18: 3.92764e-11 | AL18: 5.8367e-11 | AM18: 5.58479e-11 | AN18: 4.31086e-11
A19: 07160105_1029 | B19: UMN | C19: 56 | D19: null | E19: 1000 | F19: 31 | G19: cf | H19: side 1: -3.999, side 2: 4.4872 | I19: good | J19: ok | K19: =IF(AND(N19<0.7,N19>0.2),"lev OK","lev BAD") -> lev OK | L19: =DATE(2000+MID(A19,3,2),MID(A19,5,2),MID(A19,7,2))+TIME(MID(A19,10,2),MID(A19,12,2),0) -> 42374.437 | M19: =""""&A19&"""" -> "07160105_1029" | N19: =O19-(L19-P19)*24*Q19 -> 0.40543291 | O19: 0.432 | P19: 42374.368 | Q19: =(O19-R19)/(S19-P19)/24 -> 0.016101266 | R19: 0.326 | S19: 42374.642 | Z19: 262 | AA19: 19 | AC19: 5.67336e-11 | AD19: 4.47163e-11 | AE19: 4.79008e-11 | AF19: 3.6152e-11 | AG19: 6.18897e-11 | AH19: 6.12255e-11 | AI19: 3.36714e-11 | AJ19: 6.71865e-11 | AK19: 3.8716e-11 | AL19: 5.87484e-11 | AM19: 4.70746e-11 | AN19: 9.09463e-11
A20: 07160105_1127 | B20: UMN | C20: 56 | D20: null | E20: 1000 | F20: 31 | G20: cf | H20: side 1: -3.999, side 2: 4.4872 | I20: good | J20: ok | K20: =IF(AND(N20<0.7,N20>0.2),"lev OK","lev BAD") -> lev OK | L20: =DATE(2000+MID(A20,3,2),MID(A20,5,2),MID(A20,7,2))+TIME(MID(A20,10,2),MID(A20,12,2),0) -> 42374.477 | M20: =M19&", """&A20&"""" -> "07160105_1029", "07160105_1127" | N20: =O20-(L20-P20)*24*Q20 -> 0.38986835 | O20: 0.432 | P20: 42374.368 | Q20: =Q19 -> 0.016101266 | Z20: 171 | AA20: 61 | AC20: 1.15698e-10 | AD20: 8.81231e-11 | AE20: 1.0353e-10 | AF20: 1.00304e-10 | AG20: 1.16034e-10 | AH20: 1.21705e-10 | AI20: 6.28988e-11 | AJ20: 1.36976e-10 | AK20: 5.6914e-11 | AL20: 1.21035e-10 | AM20: 1.15691e-10 | AN20: 1.44942e-10
A21: 07160105_1234 | B21: UMN | C21: 56 | D21: null | E21: 1000 | F21: 31 | G21: cf | H21: side 1: -3.999, side 2: 4.4872 | I21: good | J21: ok | K21: =IF(AND(N21<0.7,N21>0.2),"lev OK","lev BAD") -> lev OK | L21: =DATE(2000+MID(A21,3,2),MID(A21,5,2),MID(A21,7,2))+TIME(MID(A21,10,2),MID(A21,12,2),0) -> 42374.524 | M21: =M20&", """&A21&"""" -> "07160105_1029", "07160105_1127", "07160105_1234" | N21: =O21-(L21-P21)*24*Q21 -> 0.37188861 | O21: 0.432 | P21: 42374.368 | Q21: =Q20 -> 0.016101266 | Z21: 254 | AA21: 28 | AC21: 9.95967e-11 | AD21: 7.592e-11 | AE21: 8.69734e-11 | AF21: 7.73955e-11 | AG21: 9.01018e-11 | AH21: 1.04282e-10 | AI21: 5.33707e-11 | AJ21: 1.16648e-10 | AK21: 5.11662e-11 | AL21: 1.07008e-10 | AM21: 9.80487e-11 | AN21: 1.51423e-10
A22: 07160105_1333 | B22: UMN | C22: 56 | D22: null | E22: 1000 | F22: 32 | G22: cf | H22: side 1: -3.999, side 2: 4.4872 | I22: good | J22: no PAS2 | K22: =IF(AND(N22<0.7,N22>0.2),"lev OK","lev BAD") -> lev OK | L22: =DATE(2000+MID(A22,3,2),MID(A22,5,2),MID(A22,7,2))+TIME(MID(A22,10,2),MID(A22,12,2),0) -> 42374.565 | M22: =M21&", """&A22&"""" -> "07160105_1029", "07160105_1127", "07160105_1234", "07160105_1333" | N22: =O22-(L22-P22)*24*Q22 -> 0.3560557 | O22: 0.432 | P22: 42374.368 | Q22: =Q21 -> 0.016101266 | Z22: 254 | AA22: 41 | AC22: 1.0091e-10 | AD22: 7.76538e-11 | AE22: 8.80826e-11 | AF22: 6.06358e-11 | AG22: 1.11663e-10 | AH22: 1.01736e-10 | AI22: 0 | AJ22: 1.17086e-10 | AK22: 5.07263e-11 | AL22: 1.04554e-10 | AM22: 9.06901e-11 | AN22: 1.38237e-10
A23: 07160105_1429 | B23: UMN | C23: 56 | D23: null | E23: 1000 | F23: 32 | G23: cf | H23: side 1: -3.999, side 2: 4.4872 | I23: good | J23: no PAS2 | K23: =IF(AND(N23<0.7,N23>0.2),"lev OK","lev BAD") -> lev OK | L23: =DATE(2000+MID(A23,3,2),MID(A23,5,2),MID(A23,7,2))+TIME(MID(A23,10,2),MID(A23,12,2),0) -> 42374.603 | M23: =M22&", """&A23&"""" -> "07160105_1029", "07160105_1127", "07160105_1234", "07160105_1333", "07160105_1429" | N23: =O23-(L23-P23)*24*Q23 -> 0.34102785 | O23: 0.432 | P23: 42374.368 | Q23: =Q22 -> 0.016101266 | Z23: 375 | AA23: 22 | AC23: 6.95923e-11 | AD23: 5.41228e-11 | AE23: 6.74811e-11 | AF23: 4.51663e-11 | AG23: 7.73777e-11 | AH23: 7.49111e-11 | AI23: 0 | AJ23: 8.17707e-11 | AK23: 4.09679e-11 | AL23: 7.30095e-11 | AM23: 6.49491e-11 | AN23: 1.19934e-10
A24: 07160105_1709 | B24: UMN | C24: 56 | D24: null | E24: 1000 | F24: 31 | G24: cf | H24: side 1: -3.999, side 2: 4.4872 | I24: good | J24: ok | K24: =IF(AND(N24<0.7,N24>0.2),"lev OK","lev BAD") -> lev BAD | L24: =DATE(2000+MID(A24,3,2),MID(A24,5,2),MID(A24,7,2))+TIME(MID(A24,10,2),MID(A24,12,2),0) -> 42374.715 | M24: =M23&", """&A24&"""" -> "07160105_1029", "07160105_1127", "07160105_1234", "07160105_1333", "07160105_1429", "07160105_1709" | N24: =O24-(L24-P24)*24*Q24 -> 0.91373299 | O24: 0.927 | P24: 42374.684 | Q24: =(O24-R24)/(S24-P24)/24 -> 0.018091371 | R24: 0.63 | S24: 42375.368 | Z24: 242 | AA24: 27 | AC24: 2.5341e-10 | AD24: 2.08243e-10 | AE24: 2.1903e-10 | AF24: 1.46091e-10 | AG24: 2.43269e-10 | AH24: 2.2115e-10 | AI24: 1.00308e-10 | AJ24: 2.68887e-10 | AK24: 9.10793e-11 | AL24: 2.57869e-10 | AM24: 3.31864e-10 | AN24: 1.96347e-10
A25: 07160105_1806 | B25: UMN | C25: 56 | D25: null | E25: 1000 | F25: 31 | G25: cf | H25: side 1: -3.999, side 2: 4.4872 | I25: good | J25: no phonons | K25: =IF(AND(N25<0.7,N25>0.2),"lev OK","lev BAD") -> lev BAD | L25: =DATE(2000+MID(A25,3,2),MID(A25,5,2),MID(A25,7,2))+TIME(MID(A25,10,2),MID(A25,12,2),0) -> 42374.754 | M25: =M24&", """&A25&"""" -> "07160105_1029", "07160105_1127", "07160105_1234", "07160105_1333", "07160105_1429", "07160105_1709", "07160105_1806" | N25: =O25-(L25-P25)*24*Q25 -> 0.89654619 | O25: 0.927 | P25: 42374.684 | Q25: =Q24 -> 0.018091371 | T25: 265 | V25: =(173+188)/2 -> 180.5 | Z25: 229 | AA25: 24 | AC25: 0 | AD25: 0 | AE25: 0 | AF25: 0 | AG25: 0 | AH25: 0 | AI25: 0 | AJ25: 0 | AK25: 0 | AL25: 0 | AM25: 0 | AN25: 0
A26: 07160105_1902 | B26: UMN | C26: 56 | D26: null | E26: 1000 | F26: 31 | G26: cf | H26: side 1: -3.999, side 2: 4.4872 | I26: good | J26: no phonons | K26: =IF(AND(N26<0.7,N26>0.2),"lev OK","lev BAD") -> lev BAD | L26: =DATE(2000+MID(A26,3,2),MID(A26,5,2),MID(A26,7,2))+TIME(MID(A26,10,2),MID(A26,12,2),0) -> 42374.793 | M26: =M25&", """&A26&"""" -> "07160105_1029", "07160105_1127", "07160105_1234", "07160105_1333", "07160105_1429", "07160105_1709", "07160105_1806", "07160105_1902" | N26: =O26-(L26-P26)*24*Q26 -> 0.87966091 | O26: 0.927 | P26: 42374.684 | Q26: =Q25 -> 0.018091371 | Z26: 209 | AA26: 34 | AC26: 0 | AD26: 0 | AE26: 0 | AF26: 0 | AG26: 0 | AH26: 0 | AI26: 0 | AJ26: 0 | AK26: 0 | AL26: 0 | AM26: 0 | AN26: 0
A27: 07160105_1959 | B27: UMN | C27: 56 | D27: null | E27: 1000 | F27: 31 | G27: cf | H27: side 1: -3.999, side 2: 4.4872 | I27: good | J27: no phonons | K27: =IF(AND(N27<0.7,N27>0.2),"lev OK","lev BAD") -> lev BAD | L27: =DATE(2000+MID(A27,3,2),MID(A27,5,2),MID(A27,7,2))+TIME(MID(A27,10,2),MID(A27,12,2),0) -> 42374.833 | M27: =M26&", """&A27&"""" -> "07160105_1029", "07160105_1127", "07160105_1234", "07160105_1333", "07160105_1429", "07160105_1709", "07160105_1806", "07160105_1902", "07160105_1959" | N27: =O27-(L27-P27)*24*Q27 -> 0.86247411 | O27: 0.927 | P27: 42374.684 | Q27: =Q26 -> 0.018091371 | AC27: 0 | AD27: 0 | AE27: 0 | AF27: 0 | AG27: 0 | AH27: 0 | AI27: 0 | AJ27: 0 | AK27: 0 | AL27: 0 | AM27: 0 | AN27: 0
A28: 07160105_2056 | B28: UMN | C28: 56 | D28: null | E28: 1000 | F28: 31 | G28: cf | H28: side 1: -3.999, side 2: 4.4872 | I28: good | J28: no phonons | K28: =IF(AND(N28<0.7,N28>0.2),"lev OK","lev BAD") -> lev BAD | L28: =DATE(2000+MID(A28,3,2),MID(A28,5,2),MID(A28,7,2))+TIME(MID(A28,10,2),MID(A28,12,2),0) -> 42374.872 | M28: =M27&", """&A28&"""" -> "07160105_1029", "07160105_1127", "07160105_1234", "07160105_1333", "07160105_1429", "07160105_1709", "07160105_1806", "07160105_1902", "07160105_1959", "07160105_2056" | N28: =O28-(L28-P28)*24*Q28 -> 0.84528731 | O28: 0.927 | P28: 42374.684 | Q28: =Q27 -> 0.018091371 | T28: 187 | V28: 174 | Z28: =AVERAGE((Z18:Z26)) -> 239.66667 | AA28: =AVERAGE((AA18:AA26)) -> 33.555556 | AC28: 0 | AD28: 0 | AE28: 0 | AF28: 0 | AG28: 0 | AH28: 0 | AI28: 0 | AJ28: 0 | AK28: 0 | AL28: 0 | AM28: 0 | AN28: 0
A29: 07160105_2152 | B29: UMN | C29: 56 | D29: null | E29: 1000 | F29: 31 | G29: cf | H29: side 1: -3.999, side 2: 4.4872 | I29: good | J29: no phonons | K29: =IF(AND(N29<0.7,N29>0.2),"lev OK","lev BAD") -> lev BAD | L29: =DATE(2000+MID(A29,3,2),MID(A29,5,2),MID(A29,7,2))+TIME(MID(A29,10,2),MID(A29,12,2),0) -> 42374.911 | M29: =M28&", """&A29&"""" -> "07160105_1029", "07160105_1127", "07160105_1234", "07160105_1333", "07160105_1429", "07160105_1709", "07160105_1806", "07160105_1902", "07160105_1959", "07160105_2056", "07160105_2152" | N29: =O29-(L29-P29)*24*Q29 -> 0.82840203 | O29: 0.927 | P29: 42374.684 | Q29: =Q28 -> 0.018091371 | Z29: =STDEV(Z18:Z26) -> 62.437969 | AA29: =STDEV(AA18:AA26) -> 13.574895 | AC29: 0 | AD29: 0 | AE29: 0 | AF29: 0 | AG29: 0 | AH29: 0 | AI29: 0 | AJ29: 0 | AK29: 0 | AL29: 0 | AM29: 0 | AN29: 0
A30: 07160105_2249 | B30: UMN | C30: 56 | D30: null | E30: 1000 | F30: 31 | G30: cf | H30: side 1: -3.999, side 2: 4.4872 | I30: good | J30: no phonons | K30: =IF(AND(N30<0.7,N30>0.2),"lev OK","lev BAD") -> lev BAD | L30: =DATE(2000+MID(A30,3,2),MID(A30,5,2),MID(A30,7,2))+TIME(MID(A30,10,2),MID(A30,12,2),0) -> 42374.951 | M30: =M29&", """&A30&"""" -> "07160105_1029", "07160105_1127", "07160105_1234", "07160105_1333", "07160105_1429", "07160105_1709", "07160105_1806", "07160105_1902", "07160105_1959", "07160105_2056", "07160105_2152", "07160105_2249" | N30: =O30-(L30-P30)*24*Q30 -> 0.81121523 | O30: 0.927 | P30: 42374.684 | Q30: =Q29 -> 0.018091371 | AC30: 0 | AD30: 0 | AE30: 0 | AF30: 0 | AG30: 0 | AH30: 0 | AI30: 0 | AJ30: 0 | AK30: 0 | AL30: 0 | AM30: 0 | AN30: 0
A31: 07160105_2346 | B31: UMN | C31: 56 | D31: null | E31: 1000 | F31: 31 | G31: cf | H31: side 1: -3.999, side 2: 4.4872 | I31: good | J31: ok | K31: =IF(AND(N31<0.7,N31>0.2),"lev OK","lev BAD") -> lev BAD | L31: =DATE(2000+MID(A31,3,2),MID(A31,5,2),MID(A31,7,2))+TIME(MID(A31,10,2),MID(A31,12,2),0) -> 42374.99 | M31: =M30&", """&A31&"""" -> "07160105_1029", "07160105_1127", "07160105_1234", "07160105_1333", "07160105_1429", "07160105_1709", "07160105_1806", "07160105_1902", "07160105_1959", "07160105_2056", "07160105_2152", "07160105_2249", "07160105_2346" | N31: =O31-(L31-P31)*24*Q31 -> 0.79402843 | O31: 0.927 | P31: 42374.684 | Q31: =Q30 -> 0.018091371 | T31: 233 | V31: 99 | AC31: 7.86898e-10 | AD31: 5.13919e-10 | AE31: 4.74525e-10 | AF31: 3.9569e-10 | AG31: 4.19569e-10 | AH31: 6.08306e-10 | AI31: 2.80401e-10 | AJ31: 7.10553e-10 | AK31: 1.92848e-10 | AL31: 7.27767e-10 | AM31: 6.26329e-10 | AN31: 3.08868e-10
A32: 07160106_0043 | B32: UMN | C32: 56 | D32: null | E32: 1000 | F32: 31 | G32: cf | H32: side 1: -3.999, side 2: 4.4872 | I32: good | J32: no phonons | K32: =IF(AND(N32<0.7,N32>0.2),"lev OK","lev BAD") -> lev BAD | L32: =DATE(2000+MID(A32,3,2),MID(A32,5,2),MID(A32,7,2))+TIME(MID(A32,10,2),MID(A32,12,2),0) -> 42375.03 | M32: =M31&", """&A32&"""" -> "07160105_1029", "07160105_1127", "07160105_1234", "07160105_1333", "07160105_1429", "07160105_1709", "07160105_1806", "07160105_1902", "07160105_1959", "07160105_2056", "07160105_2152", "07160105_2249", "07160105_2346", "07160106_0043" | N32: =O32-(L32-P32)*24*Q32 -> 0.77684162 | O32: 0.927 | P32: 42374.684 | Q32: =Q31 -> 0.018091371 | AC32: 0 | AD32: 0 | AE32: 0 | AF32: 0 | AG32: 0 | AH32: 0 | AI32: 0 | AJ32: 0 | AK32: 0 | AL32: 0 | AM32: 0 | AN32: 0
A33: 07160106_0139 | B33: UMN | C33: 56 | D33: null | E33: 1000 | F33: 32 | G33: cf | H33: side 1: -3.999, side 2: 4.4872 | I33: good | J33: ok | K33: =IF(AND(N33<0.7,N33>0.2),"lev OK","lev BAD") -> lev BAD | L33: =DATE(2000+MID(A33,3,2),MID(A33,5,2),MID(A33,7,2))+TIME(MID(A33,10,2),MID(A33,12,2),0) -> 42375.069 | M33: =M32&", """&A33&"""" -> "07160105_1029", "07160105_1127", "07160105_1234", "07160105_1333", "07160105_1429", "07160105_1709", "07160105_1806", "07160105_1902", "07160105_1959", "07160105_2056", "07160105_2152", "07160105_2249", "07160105_2346", "07160106_0043", "07160106_0139" | N33: =O33-(L33-P33)*24*Q33 -> 0.75995635 | O33: 0.927 | P33: 42374.684 | Q33: =Q32 -> 0.018091371 | AC33: 1.04813e-09 | AD33: 8.61231e-10 | AE33: 8.72287e-10 | AF33: 5.71162e-10 | AG33: 1.02634e-09 | AH33: 8.50371e-10 | AI33: 4.01337e-10 | AJ33: 1.07394e-09 | AK33: 3.45873e-10 | AL33: 1.0289e-09 | AM33: 8.93e-10 | AN33: 6.96921e-10
A34: 07160106_0236 | B34: UMN | C34: 56 | D34: null | E34: 1000 | F34: 32 | G34: cf | H34: side 1: -3.999, side 2: 4.4872 | I34: good | J34: ok | K34: =IF(AND(N34<0.7,N34>0.2),"lev OK","lev BAD") -> lev BAD | L34: =DATE(2000+MID(A34,3,2),MID(A34,5,2),MID(A34,7,2))+TIME(MID(A34,10,2),MID(A34,12,2),0) -> 42375.108 | M34: =M33&", """&A34&"""" -> "07160105_1029", "07160105_1127", "07160105_1234", "07160105_1333", "07160105_1429", "07160105_1709", "07160105_1806", "07160105_1902", "07160105_1959", "07160105_2056", "07160105_2152", "07160105_2249", "07160105_2346", "07160106_0043", "07160106_0139", "07160106_0236" | N34: =O34-(L34-P34)*24*Q34 -> 0.74276954 | O34: 0.927 | P34: 42374.684 | Q34: =Q33 -> 0.018091371 | T34: 240 | U34: 34 | V34: 34 | X34: 14 | AC34: 5.97138e-10 | AD34: 4.72942e-10 | AE34: 4.84543e-10 | AF34: 3.51587e-10 | AG34: 5.84046e-10 | AH34: 5.16107e-10 | AI34: 2.2627e-10 | AJ34: 6.22069e-10 | AK34: 2.0724e-10 | AL34: 6.37848e-10 | AM34: 5.11505e-10 | AN34: 3.83523e-10
A35: 07160106_0333 | B35: UMN | C35: 56 | D35: null | E35: 1000 | F35: 31 | G35: cf | H35: side 1: -3.999, side 2: 4.4872 | I35: good | J35: ok | K35: =IF(AND(N35<0.7,N35>0.2),"lev OK","lev BAD") -> lev BAD | L35: =DATE(2000+MID(A35,3,2),MID(A35,5,2),MID(A35,7,2))+TIME(MID(A35,10,2),MID(A35,12,2),0) -> 42375.148 | M35: =M34&", """&A35&"""" -> "07160105_1029", "07160105_1127", "07160105_1234", "07160105_1333", "07160105_1429", "07160105_1709", "07160105_1806", "07160105_1902", "07160105_1959", "07160105_2056", "07160105_2152", "07160105_2249", "07160105_2346", "07160106_0043", "07160106_0139", "07160106_0236", "07160106_0333" | N35: =O35-(L35-P35)*24*Q35 -> 0.72558274 | O35: 0.927 | P35: 42374.684 | Q35: =Q34 -> 0.018091371 | AC35: 3.36012e-10 | AD35: 2.59294e-10 | AE35: 2.6187e-10 | AF35: 1.80441e-10 | AG35: 2.73266e-10 | AH35: 2.61219e-10 | AI35: 1.26868e-10 | AJ35: 3.37375e-10 | AK35: 1.07434e-10 | AL35: 3.25926e-10 | AM35: 2.83366e-10 | AN35: 2.17043e-10
A36: 07160106_0429 | B36: UMN | C36: 56 | D36: null | E36: 1000 | F36: 31 | G36: cf | H36: side 1: -3.999, side 2: 4.4872 | I36: good | J36: ok | K36: =IF(AND(N36<0.7,N36>0.2),"lev OK","lev BAD") -> lev BAD | L36: =DATE(2000+MID(A36,3,2),MID(A36,5,2),MID(A36,7,2))+TIME(MID(A36,10,2),MID(A36,12,2),0) -> 42375.187 | M36: =M35&", """&A36&"""" -> "07160105_1029", "07160105_1127", "07160105_1234", "07160105_1333", "07160105_1429", "07160105_1709", "07160105_1806", "07160105_1902", "07160105_1959", "07160105_2056", "07160105_2152", "07160105_2249", "07160105_2346", "07160106_0043", "07160106_0139", "07160106_0236", "07160106_0333", "07160106_0429" | N36: =O36-(L36-P36)*24*Q36 -> 0.70869746 | O36: 0.927 | P36: 42374.684 | Q36: =Q35 -> 0.018091371 | AC36: 1.86303e-10 | AD36: 1.46459e-10 | AE36: 1.62945e-10 | AF36: 1.09009e-10 | AG36: 1.80784e-10 | AH36: 1.66761e-10 | AI36: 7.45808e-11 | AJ36: 2.05643e-10 | AK36: 7.55583e-11 | AL36: 1.85703e-10 | AM36: 1.64102e-10 | AN36: 1.6997e-10
A37: 07160106_0526 | B37: UMN | C37: 56 | D37: null | E37: 1000 | F37: 31 | G37: cf | H37: side 1: -3.999, side 2: 4.4872 | I37: good | J37: ok | K37: =IF(AND(N37<0.7,N37>0.2),"lev OK","lev BAD") -> lev OK | L37: =DATE(2000+MID(A37,3,2),MID(A37,5,2),MID(A37,7,2))+TIME(MID(A37,10,2),MID(A37,12,2),0) -> 42375.226 | M37: =M36&", """&A37&"""" -> "07160105_1029", "07160105_1127", "07160105_1234", "07160105_1333", "07160105_1429", "07160105_1709", "07160105_1806", "07160105_1902", "07160105_1959", "07160105_2056", "07160105_2152", "07160105_2249", "07160105_2346", "07160106_0043", "07160106_0139", "07160106_0236", "07160106_0333", "07160106_0429", "07160106_0526" | N37: =O37-(L37-P37)*24*Q37 -> 0.69151066 | O37: 0.927 | P37: 42374.684 | Q37: =Q36 -> 0.018091371 | AC37: 1.11206e-10 | AD37: 1.16848e-10 | AE37: 1.01635e-10 | AF37: 6.8839e-11 | AG37: 1.02603e-10 | AH37: 1.11142e-10 | AI37: 4.86547e-11 | AJ37: 1.25661e-10 | AK37: 5.36598e-11 | AL37: 1.13815e-10 | AM37: 1.0069e-10 | AN37: 1.5865e-10
A38: 07160106_0623 | B38: UMN | C38: 56 | D38: null | E38: 1000 | F38: 31 | G38: cf | H38: side 1: -3.999, side 2: 4.4872 | I38: good | J38: ok | K38: =IF(AND(N38<0.7,N38>0.2),"lev OK","lev BAD") -> lev OK | L38: =DATE(2000+MID(A38,3,2),MID(A38,5,2),MID(A38,7,2))+TIME(MID(A38,10,2),MID(A38,12,2),0) -> 42375.266 | M38: =M37&", """&A38&"""" -> "07160105_1029", "07160105_1127", "07160105_1234", "07160105_1333", "07160105_1429", "07160105_1709", "07160105_1806", "07160105_1902", "07160105_1959", "07160105_2056", "07160105_2152", "07160105_2249", "07160105_2346", "07160106_0043", "07160106_0139", "07160106_0236", "07160106_0333", "07160106_0429", "07160106_0526", "07160106_0623" | N38: =O38-(L38-P38)*24*Q38 -> 0.67432386 | O38: 0.927 | P38: 42374.684 | Q38: =Q37 -> 0.018091371 | AC38: 1.32301e-10 | AD38: 9.94103e-11 | AE38: 1.06727e-10 | AF38: 7.65199e-11 | AG38: 1.11215e-10 | AH38: 1.22267e-10 | AI38: 5.64376e-11 | AJ38: 1.41344e-10 | AK38: 5.88432e-11 | AL38: 1.28553e-10 | AM38: 1.16178e-10 | AN38: 1.46552e-10
A39: 07160106_0720 | B39: UMN | C39: 56 | D39: null | E39: 1000 | F39: 31 | G39: cf | H39: side 1: -3.999, side 2: 4.4872 | I39: good | J39: ok | K39: =IF(AND(N39<0.7,N39>0.2),"lev OK","lev BAD") -> lev OK | L39: =DATE(2000+MID(A39,3,2),MID(A39,5,2),MID(A39,7,2))+TIME(MID(A39,10,2),MID(A39,12,2),0) -> 42375.306 | M39: =M38&", """&A39&"""" -> "07160105_1029", "07160105_1127", "07160105_1234", "07160105_1333", "07160105_1429", "07160105_1709", "07160105_1806", "07160105_1902", "07160105_1959", "07160105_2056", "07160105_2152", "07160105_2249", "07160105_2346", "07160106_0043", "07160106_0139", "07160106_0236", "07160106_0333", "07160106_0429", "07160106_0526", "07160106_0623", "07160106_0720" | N39: =O39-(L39-P39)*24*Q39 -> 0.65713706 | O39: 0.927 | P39: 42374.684 | Q39: =Q38 -> 0.018091371 | AC39: 1.75815e-10 | AD39: 1.3369e-10 | AE39: 1.48346e-10 | AF39: 1.13396e-10 | AG39: 1.57465e-10 | AH39: 1.62518e-10 | AI39: 7.31608e-11 | AJ39: 1.9317e-10 | AK39: 7.45373e-11 | AL39: 1.7758e-10 | AM39: 1.56682e-10 | AN39: 1.8358e-10
